<mujoco model="positronic_roboarm">
  <compiler angle="radian"/>
  <option timestep="0.001" integrator="implicitfast"/>
  <default>
    <default class="visual">
      <geom contype="0" conaffinity="0" group="2" rgba="0.75 0.75 0.75 1"/>
    </default>
    <default class="collision">
      <geom group="3"/>
    </default>
    <default class="motor_visual">
      <geom contype="0" conaffinity="0" group="2" rgba="1 1 1 1"/>
    </default>
    <default class="link_visual">
      <geom contype="0" conaffinity="0" group="2" rgba="1 0 1 1"/>
    </default>
    <joint actuatorfrcrange="-50 50"/>
  </default>

  <worldbody>
    <body name="link1">
      <inertial pos="0 0 0" quat="0 0.707107 0 0.707107" mass="1.01" diaginertia="0.001259 0.000851 0.000843"/>
      <joint name="joint_1" pos="0 0 0" axis="0 0 1"/>
      <site name="joint_1_site" pos="0 0 0"/>
      <!-- Motor visual and collision -->
      <geom class="motor_visual" type="cylinder" size="0.05 0.025" pos="0 0 0"/>
      <geom class="collision" type="cylinder" size="0.05 0.025" pos="0 0 0"/>
      <!-- Link visual and collision -->
      <geom class="link_visual" type="cylinder" size="0.025 0.05" pos="0 0 0.05"/>
      <geom class="collision" type="cylinder" size="0.025 0.05" pos="0 0 0.05"/>
      <body name="link2" pos="0 0 0.1" quat="0.707105 0.707108 0 0">
        <inertial pos="0 0 0" quat="0 0.707107 0 0.707107" mass="1.01" diaginertia="0.001259 0.000851 0.000843"/>
        <joint name="joint_2" pos="0 0 0" axis="0 0 1"/>
        <site name="joint_2_site" pos="0 0 0"/>
        <!-- Motor visual and collision -->
        <geom class="motor_visual" type="cylinder" size="0.05 0.025" pos="0 0 0"/>
        <geom class="collision" type="cylinder" size="0.05 0.025" pos="0 0 0"/>
        <!-- Link visual and collision -->
        <geom class="link_visual" type="cylinder" size="0.025 0.05" pos="0 0 0.05"/>
        <geom class="collision" type="cylinder" size="0.025 0.05" pos="0 0 0.05"/>
        <body name="link3" pos="0 0 0.1" quat="0.707105 -0.707108 0 0">
          <inertial pos="0 0 0" quat="0 0.707107 0 0.707107" mass="1.01" diaginertia="0.001259 0.000851 0.000843"/>
          <joint name="joint_3" pos="0 0 0" axis="0 0 1"/>
          <site name="joint_3_site" pos="0 0 0"/>
          <!-- Motor visual and collision -->
          <geom class="motor_visual" type="cylinder" size="0.05 0.025" pos="0 0 0"/>
          <geom class="collision" type="cylinder" size="0.05 0.025" pos="0 0 0"/>
          <!-- Link visual and collision -->
          <geom class="link_visual" type="cylinder" size="0.025 0.1" pos="0 0 0.1"/>
          <geom class="collision" type="cylinder" size="0.025 0.1" pos="0 0 0.1"/>
          <body name="link4" pos="0 0 0.25" quat="0.707105 0.707108 0 0">
            <inertial pos="0 0 0" quat="0 0.707107 0 0.707107" mass="1.01" diaginertia="0.001259 0.000851 0.000843"/>
            <joint name="joint_4" pos="0 0 0" axis="0 0 1"/>
            <site name="joint_4_site" pos="0 0 0"/>
            <!-- Motor visual and collision -->
            <geom class="motor_visual" type="cylinder" size="0.05 0.025" pos="0 0 0"/>
            <geom class="collision" type="cylinder" size="0.05 0.025" pos="0 0 0"/>
            <!-- Link visual and collision -->
            <geom class="link_visual" type="cylinder" size="0.025 0.05" pos="0 0 0.05"/>
            <geom class="collision" type="cylinder" size="0.025 0.05" pos="0 0 0.05"/>
            <body name="link5" pos="0 0 0.1" quat="0.707105 -0.707108 0 0">
              <inertial pos="0 0 0" quat="0 0.707107 0 0.707107" mass="1.01" diaginertia="0.001259 0.000851 0.000843"/>
              <joint name="joint_5" pos="0 0 0" axis="0 0 1"/>
              <site name="joint_5_site" pos="0 0 0"/>
              <!-- Motor visual and collision -->
              <geom class="motor_visual" type="cylinder" size="0.05 0.025" pos="0 0 0"/>
              <geom class="collision" type="cylinder" size="0.05 0.025" pos="0 0 0"/>
              <!-- Link visual and collision -->
              <geom class="link_visual" type="cylinder" size="0.025 0.1" pos="0 0 0.1"/>
              <geom class="collision" type="cylinder" size="0.025 0.1" pos="0 0 0.1"/>
              <body name="link6" pos="0 0 0.25" quat="0.707105 0.707108 0 0">
                <inertial pos="0 0 0" quat="0 0.707107 0 0.707107" mass="1.01" diaginertia="0.001259 0.000851 0.000843"/>
                <joint name="joint_6" pos="0 0 0" axis="0 0 1"/>
                <site name="joint_6_site" pos="0 0 0"/>
                <!-- Motor visual and collision -->
                <geom class="motor_visual" type="cylinder" size="0.05 0.025" pos="0 0 0"/>
                <geom class="collision" type="cylinder" size="0.05 0.025" pos="0 0 0"/>
                <site name="end_effector" pos="0 0 0"/>
                <body name="payload" pos="0 0 0.1">
                  <inertial pos="0 0 0" mass="2" diaginertia="0.00333333 0.00166667 0.00166667"/>
                </body>
              </body>
            </body>
          </body>
        </body>
      </body>
    </body>
  </worldbody>

  <actuator>
    <position name="actuator_1" joint="joint_1" kp="1000" kv="100" ctrlrange="-1.5708 1.5708"/>
    <position name="actuator_2" joint="joint_2" kp="1000" kv="100" ctrlrange="-1.5708 1.5708"/>
    <position name="actuator_3" joint="joint_3" kp="1000" kv="100" ctrlrange="-1.5708 1.5708"/>
    <position name="actuator_4" joint="joint_4" kp="1000" kv="100" ctrlrange="-1.5708 1.5708"/>
    <position name="actuator_5" joint="joint_5" kp="1000" kv="100" ctrlrange="-1.5708 1.5708"/>
    <position name="actuator_6" joint="joint_6" kp="1000" kv="100" ctrlrange="-1.5708 1.5708"/>
  </actuator>

  <sensor>
    <torque name="torque_1" site="joint_1_site"/>
    <torque name="torque_2" site="joint_2_site"/>
    <torque name="torque_3" site="joint_3_site"/>
    <torque name="torque_4" site="joint_4_site"/>
    <torque name="torque_5" site="joint_5_site"/>
    <torque name="torque_6" site="joint_6_site"/>
  </sensor>
</mujoco>
