<?xml version="1.0"?>


<robot name="positronic_roboarm">
  <material name="motor_color">
    <color rgba="1 1 1 1"/>
  </material>
  <material name="link_color">
    <color rgba="1 0 1 1"/>
  </material>
  <link name="base"/>
  <link name="link1">
    <inertial>
      <origin rpy="0 0 0" xyz="0 0 0"/>
      <mass value="1.01"/>
      <inertia ixx="0.000843" ixy="0.000000" ixz="0.000000"
              iyy="0.000851" iyz="0.000000" izz="0.001259"/>
    </inertial>
    <visual>
      <origin rpy="0 0 0" xyz="0 0 0"/>
      <geometry>
        <cylinder length="0.05" radius="0.05"/>
      </geometry>
      <material name="motor_color"/>
    </visual>
    <visual>
      <origin rpy="0 0 0" xyz="0 0 0.05"/>
      <geometry>
        <cylinder length="0.1" radius="0.025"/>
      </geometry>
      <material name="link_color"/>
    </visual>
  </link>
  <joint name="joint_1" type="continuous">
    <origin rpy="0 0 0" xyz="0 0 0"/>
    <parent link="base"/>
    <child link="link1"/>
    <axis xyz="0 0 1"/>
    <limit effort="100" velocity="1"/>
  </joint>
  <link name="link2">
    <inertial>
      <origin rpy="0 0 0" xyz="0 0 0"/>
      <mass value="1.01"/>
      <inertia ixx="0.000843" ixy="0.000000" ixz="0.000000"
              iyy="0.000851" iyz="0.000000" izz="0.001259"/>
    </inertial>
    <visual>
      <origin rpy="0 0 0" xyz="0 0 0"/>
      <geometry>
        <cylinder length="0.05" radius="0.05"/>
      </geometry>
      <material name="motor_color"/>
    </visual>
    <visual>
      <origin rpy="0 0 0" xyz="0 0 0.05"/>
      <geometry>
        <cylinder length="0.1" radius="0.025"/>
      </geometry>
      <material name="link_color"/>
    </visual>
  </link>
  <joint name="joint_2" type="continuous">
    <origin rpy="1.5708 0 0" xyz="0 0 0.1"/>
    <parent link="link1"/>
    <child link="link2"/>
    <axis xyz="0 0 1"/>
    <limit effort="100" velocity="1"/>
  </joint>
  <link name="link3">
    <inertial>
      <origin rpy="0 0 0" xyz="0 0 0"/>
      <mass value="1.01"/>
      <inertia ixx="0.000843" ixy="0.000000" ixz="0.000000"
              iyy="0.000851" iyz="0.000000" izz="0.001259"/>
    </inertial>
    <visual>
      <origin rpy="0 0 0" xyz="0 0 0"/>
      <geometry>
        <cylinder length="0.05" radius="0.05"/>
      </geometry>
      <material name="motor_color"/>
    </visual>
    <visual>
      <origin rpy="0 0 0" xyz="0 0 0.1"/>
      <geometry>
        <cylinder length="0.2" radius="0.025"/>
      </geometry>
      <material name="link_color"/>
    </visual>
  </link>
  <joint name="joint_3" type="continuous">
    <origin rpy="-1.5708 0 0" xyz="0 0 0.1"/>
    <parent link="link2"/>
    <child link="link3"/>
    <axis xyz="0 0 1"/>
    <limit effort="100" velocity="1"/>
  </joint>
  <link name="link4">
    <inertial>
      <origin rpy="0 0 0" xyz="0 0 0"/>
      <mass value="1.01"/>
      <inertia ixx="0.000843" ixy="0.000000" ixz="0.000000"
              iyy="0.000851" iyz="0.000000" izz="0.001259"/>
    </inertial>
    <visual>
      <origin rpy="0 0 0" xyz="0 0 0"/>
      <geometry>
        <cylinder length="0.05" radius="0.05"/>
      </geometry>
      <material name="motor_color"/>
    </visual>
    <visual>
      <origin rpy="0 0 0" xyz="0 0 0.05"/>
      <geometry>
        <cylinder length="0.1" radius="0.025"/>
      </geometry>
      <material name="link_color"/>
    </visual>
  </link>
  <joint name="joint_4" type="continuous">
    <origin rpy="1.5708 0 0" xyz="0 0 0.25"/>
    <parent link="link3"/>
    <child link="link4"/>
    <axis xyz="0 0 1"/>
    <limit effort="100" velocity="1"/>
  </joint>
  <link name="link5">
    <inertial>
      <origin rpy="0 0 0" xyz="0 0 0"/>
      <mass value="1.01"/>
      <inertia ixx="0.000843" ixy="0.000000" ixz="0.000000"
              iyy="0.000851" iyz="0.000000" izz="0.001259"/>
    </inertial>
    <visual>
      <origin rpy="0 0 0" xyz="0 0 0"/>
      <geometry>
        <cylinder length="0.05" radius="0.05"/>
      </geometry>
      <material name="motor_color"/>
    </visual>
    <visual>
      <origin rpy="0 0 0" xyz="0 0 0.1"/>
      <geometry>
        <cylinder length="0.2" radius="0.025"/>
      </geometry>
      <material name="link_color"/>
    </visual>
  </link>
  <joint name="joint_5" type="continuous">
    <origin rpy="-1.5708 0 0" xyz="0 0 0.1"/>
    <parent link="link4"/>
    <child link="link5"/>
    <axis xyz="0 0 1"/>
    <limit effort="100" velocity="1"/>
  </joint>
  <link name="link6">
    <inertial>
      <origin rpy="0 0 0" xyz="0 0 0"/>
      <mass value="1.01"/>
      <inertia ixx="0.000843" ixy="0.000000" ixz="0.000000"
              iyy="0.000851" iyz="0.000000" izz="0.001259"/>
    </inertial>
    <visual>
      <origin rpy="0 0 0" xyz="0 0 0"/>
      <geometry>
        <cylinder length="0.05" radius="0.05"/>
      </geometry>
      <material name="motor_color"/>
    </visual>
  </link>
  <joint name="joint_6" type="continuous">
    <origin rpy="1.5708 0 0" xyz="0 0 0.25"/>
    <parent link="link5"/>
    <child link="link6"/>
    <axis xyz="0 0 1"/>
    <limit effort="100" velocity="1"/>
  </joint>
</robot>
