<mujoco model="panda">
  <compiler angle="radian" meshdir="assets/"/>

  <default>
    <default class="panda">
      <material shininess="0.25"/>
      <joint range="-2.8973 2.8973" armature="0.1" damping="1"/>
      <general ctrlrange="-2.8973 2.8973" forcerange="-100 100" biastype="affine" biasprm="0 -1"/>
      <default class="finger">
        <joint type="slide" range="0 0.04"/>
      </default>
      <default class="visual">
        <geom type="mesh" contype="0" conaffinity="0" group="2"/>
      </default>
      <default class="collision">
        <geom type="mesh" contype="0" conaffinity="0" group="3"/>
        <default class="primitive_collision">
          <geom type="box" solref="0.01" solimp="0.99 0.995 0.01"/>
          <default class="fingertip_pad_collision_1">
            <geom size="0.011 0.0075 0.01"/>
          </default>
          <default class="fingertip_pad_collision_2">
            <geom size="0.011 0.0044 0.0019"/>
          </default>
          <default class="fingertip_pad_collision_3">
            <geom size="0.00875 0.0035 0.01175"/>
          </default>
          <default class="fingertip_pad_collision_4">
            <geom size="0.00875 0.0076 0.00825" conaffinity="3"/>
          </default>
        </default>
      </default>
    </default>
    <default class="mainrq">
      <default class="2f85rq">
        <mesh scale="0.001 0.001 0.001"/>
        <general biastype="affine"/>
        <default class="driverrq">
          <joint solreflimit="0.005" solimplimit="0.95 0.99" range="0 0.8" armature="0.005" damping="0.1"/>
        </default>
        <default class="followerrq">
          <joint solreflimit="0.005" solimplimit="0.95 0.99" range="-0.872664 0.872664" armature="0.001"/>
        </default>
        <default class="spring_linkrq">
          <joint springref="2.62" stiffness="0.05" range="-0.296706 0.8" armature="0.001" damping="0.00125"/>
        </default>
        <default class="couplerrq">
          <joint solreflimit="0.005" solimplimit="0.95 0.99" range="-1.57 0" armature="0.001"/>
        </default>
        <default class="visualrq">
          <geom type="mesh" contype="0" conaffinity="0" group="2"/>
        </default>
        <default class="collisionrq">
          <geom type="mesh" group="3"/>
          <default class="pad_box1rq">
            <geom size="0.011 0.004 0.009375" type="box" priority="1" friction="0.7" solref="0.004" solimp="0.95 0.99" rgba="0.55 0.55 0.55 1"/>
          </default>
          <default class="pad_box2rq">
            <geom size="0.011 0.004 0.009375" type="box" priority="1" friction="0.6" solref="0.004" solimp="0.95 0.99" rgba="0.45 0.45 0.45 1"/>
          </default>
        </default>
      </default>
    </default>
  </default>

  <asset>
    <material name="white" class="panda"/>
    <material name="off_white" class="panda" rgba="0.901961 0.921569 0.929412 1"/>
    <material name="black" class="panda" rgba="0.25 0.25 0.25 1"/>
    <material name="green" class="panda" rgba="0 1 0 1"/>
    <material name="light_blue" class="panda" rgba="0.039216 0.541176 0.780392 1"/>
    <material name="metalrq" rgba="0.58 0.58 0.58 1"/>
    <material name="siliconerq" rgba="0.1882 0.1882 0.1882 1"/>
    <material name="grayrq" rgba="0.4627 0.4627 0.4627 1"/>
    <material name="blackrq" rgba="0.149 0.149 0.149 1"/>
    <mesh name="link0_c" file="link0.stl"/>
    <mesh name="link1_c" file="link1.stl"/>
    <mesh name="link2_c" file="link2.stl"/>
    <mesh name="link3_c" file="link3.stl"/>
    <mesh name="link4_c" file="link4.stl"/>
    <mesh name="link5_c0" file="link5_collision_0.obj"/>
    <mesh name="link5_c1" file="link5_collision_1.obj"/>
    <mesh name="link5_c2" file="link5_collision_2.obj"/>
    <mesh name="link6_c" file="link6.stl"/>
    <mesh name="link7_c" file="link7.stl"/>
    <mesh name="hand_c" file="hand.stl"/>
    <mesh name="link0_0" file="link0_0.obj"/>
    <mesh name="link0_1" file="link0_1.obj"/>
    <mesh name="link0_2" file="link0_2.obj"/>
    <mesh name="link0_3" file="link0_3.obj"/>
    <mesh name="link0_4" file="link0_4.obj"/>
    <mesh name="link0_5" file="link0_5.obj"/>
    <mesh name="link0_7" file="link0_7.obj"/>
    <mesh name="link0_8" file="link0_8.obj"/>
    <mesh name="link0_9" file="link0_9.obj"/>
    <mesh name="link0_10" file="link0_10.obj"/>
    <mesh name="link0_11" file="link0_11.obj"/>
    <mesh name="link1" file="link1.obj"/>
    <mesh name="link2" file="link2.obj"/>
    <mesh name="link3_0" file="link3_0.obj"/>
    <mesh name="link3_1" file="link3_1.obj"/>
    <mesh name="link3_2" file="link3_2.obj"/>
    <mesh name="link3_3" file="link3_3.obj"/>
    <mesh name="link4_0" file="link4_0.obj"/>
    <mesh name="link4_1" file="link4_1.obj"/>
    <mesh name="link4_2" file="link4_2.obj"/>
    <mesh name="link4_3" file="link4_3.obj"/>
    <mesh name="link5_0" file="link5_0.obj"/>
    <mesh name="link5_1" file="link5_1.obj"/>
    <mesh name="link5_2" file="link5_2.obj"/>
    <mesh name="link6_0" file="link6_0.obj"/>
    <mesh name="link6_1" file="link6_1.obj"/>
    <mesh name="link6_2" file="link6_2.obj"/>
    <mesh name="link6_3" file="link6_3.obj"/>
    <mesh name="link6_4" file="link6_4.obj"/>
    <mesh name="link6_5" file="link6_5.obj"/>
    <mesh name="link6_6" file="link6_6.obj"/>
    <mesh name="link6_7" file="link6_7.obj"/>
    <mesh name="link6_8" file="link6_8.obj"/>
    <mesh name="link6_9" file="link6_9.obj"/>
    <mesh name="link6_10" file="link6_10.obj"/>
    <mesh name="link6_11" file="link6_11.obj"/>
    <mesh name="link6_12" file="link6_12.obj"/>
    <mesh name="link6_13" file="link6_13.obj"/>
    <mesh name="link6_14" file="link6_14.obj"/>
    <mesh name="link6_15" file="link6_15.obj"/>
    <mesh name="link6_16" file="link6_16.obj"/>
    <mesh name="link7_0" file="link7_0.obj"/>
    <mesh name="link7_1" file="link7_1.obj"/>
    <mesh name="link7_2" file="link7_2.obj"/>
    <mesh name="link7_3" file="link7_3.obj"/>
    <mesh name="link7_4" file="link7_4.obj"/>
    <mesh name="link7_5" file="link7_5.obj"/>
    <mesh name="link7_6" file="link7_6.obj"/>
    <mesh name="link7_7" file="link7_7.obj"/>
    <mesh name="hand_0" file="hand_0.obj"/>
    <mesh name="hand_1" file="hand_1.obj"/>
    <mesh name="hand_2" file="hand_2.obj"/>
    <mesh name="hand_3" file="hand_3.obj"/>
    <mesh name="hand_4" file="hand_4.obj"/>
    <mesh name="finger_0" file="finger_0.obj"/>
    <mesh name="finger_1" file="finger_1.obj"/>
    <mesh name="base_mountrq" class="2f85rq" file="base_mount.stl"/>
    <mesh name="baserq" class="2f85rq" file="base.stl"/>
    <mesh name="driverrq" class="2f85rq" file="driver.stl"/>
    <mesh name="couplerrq" class="2f85rq" file="coupler.stl"/>
    <mesh name="followerrq" class="2f85rq" file="follower.stl"/>
    <mesh name="padrq" class="2f85rq" file="pad.stl"/>
    <mesh name="silicone_padrq" class="2f85rq" file="silicone_pad.stl"/>
    <mesh name="spring_linkrq" class="2f85rq" file="spring_link.stl"/>
  </asset>

  <worldbody>
    <light name="top" pos="0 0 2" dir="0 0 -1" mode="trackcom"/>
    <body name="link0" childclass="panda">
      <inertial pos="-0.041018 -0.00014 0.049974" quat="0.00630474 0.751245 0.00741774 0.659952" mass="0.629769" diaginertia="0.00430465 0.00387984 0.00313051"/>
      <geom class="visual" material="off_white" mesh="link0_0"/>
      <geom class="visual" material="black" mesh="link0_1"/>
      <geom class="visual" material="off_white" mesh="link0_2"/>
      <geom class="visual" material="black" mesh="link0_3"/>
      <geom class="visual" material="off_white" mesh="link0_4"/>
      <geom class="visual" material="black" mesh="link0_5"/>
      <geom class="visual" material="white" mesh="link0_7"/>
      <geom class="visual" material="white" mesh="link0_8"/>
      <geom class="visual" material="black" mesh="link0_9"/>
      <geom class="visual" material="off_white" mesh="link0_10"/>
      <geom class="visual" material="white" mesh="link0_11"/>
      <geom class="collision" mesh="link0_c"/>
      <body name="link1" pos="0 0 0.333">
        <inertial pos="0.003875 0.002081 -0.04762" quat="0.711549 0.00634377 -0.0131124 0.702485" mass="4.97068" diaginertia="0.707137 0.703435 0.00852456"/>
        <joint name="joint1" pos="0 0 0" axis="0 0 1" damping="40"/>
        <geom class="visual" material="white" mesh="link1"/>
        <geom class="collision" mesh="link1_c"/>
        <site name="site_joint1" pos="0 0 0"/>
        <body name="link2" quat="0.707107 -0.707107 0 0">
          <inertial pos="-0.003141 -0.02872 0.003495" quat="-0.168175 0.828366 -0.122878 0.520027" mass="0.646926" diaginertia="0.0310326 0.0283001 0.00273425"/>
          <joint name="joint2" pos="0 0 0" axis="0 0 1" range="-1.7628 1.7628" damping="40"/>
          <geom class="visual" material="white" mesh="link2"/>
          <geom class="collision" mesh="link2_c"/>
          <site name="site_joint2" pos="0 0 0"/>
          <body name="link3" pos="0 -0.316 0" quat="0.707107 0.707107 0 0">
            <inertial pos="0.027518 0.039252 -0.066502" quat="0.662769 -0.00678331 0.252053 0.705096" mass="3.2286" diaginertia="0.0415014 0.0414793 0.00124635"/>
            <joint name="joint3" pos="0 0 0" axis="0 0 1" damping="40"/>
            <geom class="visual" material="white" mesh="link3_0"/>
            <geom class="visual" material="white" mesh="link3_1"/>
            <geom class="visual" material="white" mesh="link3_2"/>
            <geom class="visual" material="black" mesh="link3_3"/>
            <geom class="collision" mesh="link3_c"/>
            <site name="site_joint3" pos="0 0 0"/>
            <body name="link4" pos="0.0825 0 0" quat="0.707107 0.707107 0 0">
              <inertial pos="-0.05317 0.104419 0.027454" quat="0.65058 0.529822 -0.0962034 0.535518" mass="3.5879" diaginertia="0.0349596 0.0281483 0.0106201"/>
              <joint name="joint4" pos="0 0 0" axis="0 0 1" range="-3.0718 -0.0698" damping="40"/>
              <geom class="visual" material="white" mesh="link4_0"/>
              <geom class="visual" material="white" mesh="link4_1"/>
              <geom class="visual" material="black" mesh="link4_2"/>
              <geom class="visual" material="white" mesh="link4_3"/>
              <geom class="collision" mesh="link4_c"/>
              <site name="site_joint4" pos="0 0 0"/>
              <body name="link5" pos="-0.0825 0.384 0" quat="0.707107 -0.707107 0 0">
                <inertial pos="-0.011953 0.041065 -0.038437" quat="0.987313 -0.0121954 0.0719187 -0.141037" mass="1.22595" diaginertia="0.0367625 0.0288531 0.00803437"/>
                <joint name="joint5" pos="0 0 0" axis="0 0 1" damping="2"/>
                <geom class="visual" material="black" mesh="link5_0"/>
                <geom class="visual" material="white" mesh="link5_1"/>
                <geom class="visual" material="white" mesh="link5_2"/>
                <geom class="collision" mesh="link5_c0"/>
                <geom class="collision" mesh="link5_c1"/>
                <geom class="collision" mesh="link5_c2"/>
                <site name="site_joint5" pos="0 0 0"/>
                <body name="link6" quat="0.707107 0.707107 0 0">
                  <inertial pos="0.060149 -0.014117 -0.010517" quat="0.101075 0.59332 0.0287227 0.798079" mass="1.66656" diaginertia="0.00584276 0.00431037 0.00159787"/>
                  <joint name="joint6" pos="0 0 0" axis="0 0 1" range="-0.0175 3.7525" damping="2"/>
                  <geom class="visual" material="off_white" mesh="link6_0"/>
                  <geom class="visual" material="white" mesh="link6_1"/>
                  <geom class="visual" material="black" mesh="link6_2"/>
                  <geom class="visual" material="white" mesh="link6_3"/>
                  <geom class="visual" material="white" mesh="link6_4"/>
                  <geom class="visual" material="white" mesh="link6_5"/>
                  <geom class="visual" material="white" mesh="link6_6"/>
                  <geom class="visual" material="light_blue" mesh="link6_7"/>
                  <geom class="visual" material="light_blue" mesh="link6_8"/>
                  <geom class="visual" material="black" mesh="link6_9"/>
                  <geom class="visual" material="black" mesh="link6_10"/>
                  <geom class="visual" material="white" mesh="link6_11"/>
                  <geom class="visual" material="green" mesh="link6_12"/>
                  <geom class="visual" material="white" mesh="link6_13"/>
                  <geom class="visual" material="black" mesh="link6_14"/>
                  <geom class="visual" material="black" mesh="link6_15"/>
                  <geom class="visual" material="white" mesh="link6_16"/>
                  <geom class="collision" mesh="link6_c"/>
                  <site name="site_joint6" pos="0 0 0"/>
                  <body name="link7" pos="0.088 0 0" quat="0.707107 0.707107 0 0">
                    <inertial pos="0.010517 -0.004252 0.061597" quat="0.992939 -0.0762041 0.0733595 -0.0537067" mass="0.735522" diaginertia="0.0127345 0.0101055 0.00451803"/>
                    <joint name="joint7" pos="0 0 0" axis="0 0 1" damping="2"/>
                    <geom class="visual" material="white" mesh="link7_0"/>
                    <geom class="visual" material="black" mesh="link7_1"/>
                    <geom class="visual" material="black" mesh="link7_2"/>
                    <geom class="visual" material="black" mesh="link7_3"/>
                    <geom class="visual" material="black" mesh="link7_4"/>
                    <geom class="visual" material="black" mesh="link7_5"/>
                    <geom class="visual" material="black" mesh="link7_6"/>
                    <geom class="visual" material="white" mesh="link7_7"/>
                    <geom class="collision" mesh="link7_c"/>
                    <site name="site_joint7" pos="0 0 0.107" quat="0.707107 0 0 0.707107"/>
                    <body name="base_mountrq" childclass="2f85rq" pos="0 0 0.114" quat="0.707107 0 0 0.707107">
                      <geom class="visualrq" material="blackrq" mesh="base_mountrq"/>
                      <geom class="collisionrq" mesh="base_mountrq"/>
                      <body name="baserq" pos="0 0 0.0038" quat="0.707107 0 0 -0.707107">
                        <inertial pos="0 -2.70394e-05 0.0354675" quat="0.999999 -0.00152849 0 0" mass="0.777441" diaginertia="0.000260285 0.000225381 0.000152708"/>
                        <geom class="visualrq" material="blackrq" mesh="baserq"/>
                        <geom class="collisionrq" mesh="baserq"/>
                        <site name="pinchrq" pos="0 0 0.145" group="5" rgba="0.9 0.9 0.9 1"/>
                        <body name="right_driverrq" pos="0 0.0306011 0.054904">
                          <inertial pos="2.96931e-12 0.0177547 0.00107314" quat="0.681301 0.732003 0 0" mass="0.00899563" diaginertia="1.72352e-06 1.60906e-06 3.22006e-07"/>
                          <joint name="right_driver_jointrq" class="driverrq" pos="0 0 0" axis="1 0 0"/>
                          <geom class="visualrq" material="grayrq" mesh="driverrq"/>
                          <geom class="collisionrq" mesh="driverrq"/>
                          <body name="right_couplerrq" pos="0 0.0315 -0.0041">
                            <inertial pos="0 0.00301209 0.0232175" quat="0.705636 -0.0455904 0.0455904 0.705636" mass="0.0140974" diaginertia="4.16206e-06 3.52216e-06 8.88131e-07"/>
                            <joint name="right_coupler_jointrq" class="couplerrq" pos="0 0 0" axis="1 0 0"/>
                            <geom class="visualrq" material="blackrq" mesh="couplerrq"/>
                            <geom class="collisionrq" mesh="couplerrq"/>
                          </body>
                        </body>
                        <body name="right_spring_linkrq" pos="0 0.0132 0.0609">
                          <inertial pos="-8.65005e-09 0.0181624 0.0212658" quat="0.663403 -0.244737 0.244737 0.663403" mass="0.0221642" diaginertia="8.96853e-06 6.71733e-06 2.63931e-06"/>
                          <joint name="right_spring_link_jointrq" class="spring_linkrq" pos="0 0 0" axis="1 0 0" springref="2.62"/>
                          <geom class="visualrq" material="blackrq" mesh="spring_linkrq"/>
                          <geom class="collisionrq" mesh="spring_linkrq"/>
                          <body name="right_followerrq" pos="0 0.055 0.0375">
                            <inertial pos="0 -0.011046 0.0124786" quat="0.986437 0.164143 0 0" mass="0.0125222" diaginertia="2.67415e-06 2.4559e-06 6.02031e-07"/>
                            <joint name="right_follower_jointrq" class="followerrq" pos="0 -0.018 0.0065" axis="1 0 0"/>
                            <geom class="visualrq" material="blackrq" mesh="followerrq"/>
                            <geom class="collisionrq" mesh="followerrq"/>
                            <body name="right_padrq" pos="0 -0.0189 0.01352">
                              <inertial pos="0 -0.0025 0.0185" quat="0.707107 0 0 0.707107" mass="0.0035" diaginertia="4.73958e-07 3.64583e-07 1.23958e-07"/>
                              <geom name="right_pad1rq" class="pad_box1rq" pos="0 -0.0026 0.028125" mass="0"/>
                              <geom name="right_pad2rq" class="pad_box2rq" pos="0 -0.0026 0.009375" mass="0"/>
                              <geom class="visualrq" mesh="padrq"/>
                              <body name="right_silicone_padrq">
                                <geom class="visualrq" material="blackrq" mesh="silicone_padrq"/>
                              </body>
                            </body>
                          </body>
                        </body>
                        <body name="left_driverrq" pos="0 -0.0306011 0.054904" quat="0 0 0 1">
                          <inertial pos="0 0.0177547 0.00107314" quat="0.681301 0.732003 0 0" mass="0.00899563" diaginertia="1.72352e-06 1.60906e-06 3.22006e-07"/>
                          <joint name="left_driver_jointrq" class="driverrq" pos="0 0 0" axis="1 0 0"/>
                          <geom class="visualrq" material="grayrq" mesh="driverrq"/>
                          <geom class="collisionrq" mesh="driverrq"/>
                          <body name="left_couplerrq" pos="0 0.0315 -0.0041">
                            <inertial pos="0 0.00301209 0.0232175" quat="0.705636 -0.0455904 0.0455904 0.705636" mass="0.0140974" diaginertia="4.16206e-06 3.52216e-06 8.88131e-07"/>
                            <joint name="left_coupler_jointrq" class="couplerrq" pos="0 0 0" axis="1 0 0"/>
                            <geom class="visualrq" material="blackrq" mesh="couplerrq"/>
                            <geom class="collisionrq" mesh="couplerrq"/>
                          </body>
                        </body>
                        <body name="left_spring_linkrq" pos="0 -0.0132 0.0609" quat="0 0 0 1">
                          <inertial pos="-8.65005e-09 0.0181624 0.0212658" quat="0.663403 -0.244737 0.244737 0.663403" mass="0.0221642" diaginertia="8.96853e-06 6.71733e-06 2.63931e-06"/>
                          <joint name="left_spring_link_jointrq" class="spring_linkrq" pos="0 0 0" axis="1 0 0" springref="2.62"/>
                          <geom class="visualrq" material="blackrq" mesh="spring_linkrq"/>
                          <geom class="collisionrq" mesh="spring_linkrq"/>
                          <body name="left_followerrq" pos="0 0.055 0.0375">
                            <inertial pos="0 -0.011046 0.0124786" quat="0.986437 0.164143 0 0" mass="0.0125222" diaginertia="2.67415e-06 2.4559e-06 6.02031e-07"/>
                            <joint name="left_follower_jointrq" class="followerrq" pos="0 -0.018 0.0065" axis="1 0 0"/>
                            <geom class="visualrq" material="blackrq" mesh="followerrq"/>
                            <geom class="collisionrq" mesh="followerrq"/>
                            <body name="left_padrq" pos="0 -0.0189 0.01352">
                              <inertial pos="0 -0.0025 0.0185" quat="0.707107 0 0 0.707107" mass="0.0035" diaginertia="4.73958e-07 3.64583e-07 1.23958e-07"/>
                              <geom name="left_pad1rq" class="pad_box1rq" pos="0 -0.0026 0.028125" mass="0"/>
                              <geom name="left_pad2rq" class="pad_box2rq" pos="0 -0.0026 0.009375" mass="0"/>
                              <geom class="visualrq" mesh="padrq"/>
                              <body name="left_silicone_padrq">
                                <geom class="visualrq" material="blackrq" mesh="silicone_padrq"/>
                              </body>
                            </body>
                          </body>
                        </body>
                      </body>
                    </body>
                  </body>
                </body>
              </body>
            </body>
          </body>
        </body>
      </body>
    </body>
  </worldbody>

  <contact>
    <exclude body1="baserq" body2="right_driverrq"/>
    <exclude body1="baserq" body2="right_spring_linkrq"/>
    <exclude body1="baserq" body2="left_driverrq"/>
    <exclude body1="baserq" body2="left_spring_linkrq"/>
    <exclude body1="right_couplerrq" body2="right_followerrq"/>
    <exclude body1="left_couplerrq" body2="left_followerrq"/>
  </contact>

  <equality>
    <connect body1="right_followerrq" body2="right_couplerrq" anchor="0 0 0" solref="0.005" solimp="0.95 0.99"/>
    <connect body1="left_followerrq" body2="left_couplerrq" anchor="0 0 0" solref="0.005" solimp="0.95 0.99"/>
    <joint joint1="right_driver_jointrq" joint2="left_driver_jointrq" polycoef="0 1 0 0 0" solref="0.005" solimp="0.95 0.99"/>
  </equality>

  <tendon>
    <fixed name="splitrq">
      <joint joint="right_driver_jointrq" coef="0.5"/>
      <joint joint="left_driver_jointrq" coef="0.5"/>
    </fixed>
  </tendon>

  <actuator>
    <general name="actuator1" class="panda" joint="joint1" gainprm="1000" biasprm="0 -1000 -20"/>
    <general name="actuator2" class="panda" joint="joint2" ctrlrange="-1.7628 1.7628" gainprm="1000" biasprm="0 -1000 -20"/>
    <general name="actuator3" class="panda" joint="joint3" gainprm="750" biasprm="0 -750 -4"/>
    <general name="actuator4" class="panda" joint="joint4" ctrlrange="-3.0718 -0.0698" gainprm="750" biasprm="0 -750 -4"/>
    <general name="actuator5" class="panda" joint="joint5" forcerange="-12 12" gainprm="300" biasprm="0 -300 -2"/>
    <general name="actuator6" class="panda" joint="joint6" ctrlrange="-0.0175 3.7525" forcerange="-12 12" gainprm="300" biasprm="0 -300 -2"/>
    <general name="actuator7" class="panda" joint="joint7" forcerange="-12 12" gainprm="300" biasprm="0 -300 -2"/>
    <general name="fingers_actuatorrq" class="2f85rq" tendon="splitrq" ctrlrange="0 255" forcerange="-5 5" gainprm="0.313725" biasprm="0 -100 -10"/>
  </actuator>

  <sensor>
    <torque site="site_joint1" name="torque1"/>
    <torque site="site_joint2" name="torque2"/>
    <torque site="site_joint3" name="torque3"/>
    <torque site="site_joint4" name="torque4"/>
    <torque site="site_joint5" name="torque5"/>
    <torque site="site_joint6" name="torque6"/>
    <torque site="site_joint7" name="torque7"/>
  </sensor>
</mujoco>
